Workbook

Sheet Living Expenses
A1: Four-Step Budget Template | C1: Updated: | J1: =IFERROR(__xludf.DUMMYFUNCTION("QUERY( FILTER( {TRIM(CLEAN(D2:D170)), VALUE(B2:B170)}, TRIM(CLEAN(D2:D170))<>"""", ISNUMBER(B2:B170) ), ""select Col1, sum(Col2) group by Col1 label Col1 'Budget Categories', sum(Col2) 'Monthly Budget Totals'"", 0 )"),"Budget Categories") -> Budget Categories | K1: =IFERROR(__xludf.DUMMYFUNCTION("""COMPUTED_VALUE"""),"Monthly Budget Totals") -> Monthly Budget Totals
A2: Luke Stimson | C2: 46151 | J2: =IFERROR(__xludf.DUMMYFUNCTION("""COMPUTED_VALUE"""),"AI Fees") -> AI Fees | K2: =IFERROR(__xludf.DUMMYFUNCTION("""COMPUTED_VALUE"""),10.0) -> 10
A3: Based on current living at 1126 Vallejo st | J3: =IFERROR(__xludf.DUMMYFUNCTION("""COMPUTED_VALUE"""),"Bar/ Alcohol") -> Bar/ Alcohol | K3: =IFERROR(__xludf.DUMMYFUNCTION("""COMPUTED_VALUE"""),100.0) -> 100
A4: Bartending & Business Building | J4: =IFERROR(__xludf.DUMMYFUNCTION("""COMPUTED_VALUE"""),"Business Expenses") -> Business Expenses | K4: =IFERROR(__xludf.DUMMYFUNCTION("""COMPUTED_VALUE"""),84.0) -> 84
A5: Modified taxable income to respect CA Standard deduction (CA taxes on more of my income) | J5: =IFERROR(__xludf.DUMMYFUNCTION("""COMPUTED_VALUE"""),"Coffee") -> Coffee | K5: =IFERROR(__xludf.DUMMYFUNCTION("""COMPUTED_VALUE"""),84.0) -> 84
A6: Auto Budgeting Flow Info: Created Budgeting/ Expenses flow: Cap one Transaction + Venmo Transaction + Other transactions auto format and populate All transactions and then these are summarized by month in the Summary 2026 sheet which groups all expenses and budget amounts and compares them. In the future I should be able to create a duplicate sheet for 2027 and just change the year cell to have everything work properly. | J6: =IFERROR(__xludf.DUMMYFUNCTION("""COMPUTED_VALUE"""),"Dining") -> Dining | K6: =IFERROR(__xludf.DUMMYFUNCTION("""COMPUTED_VALUE"""),320.0) -> 320
J7: =IFERROR(__xludf.DUMMYFUNCTION("""COMPUTED_VALUE"""),"Entertainment") -> Entertainment | K7: =IFERROR(__xludf.DUMMYFUNCTION("""COMPUTED_VALUE"""),47.5) -> 47.5
C8: Single | J8: =IFERROR(__xludf.DUMMYFUNCTION("""COMPUTED_VALUE"""),"Groceries") -> Groceries | K8: =IFERROR(__xludf.DUMMYFUNCTION("""COMPUTED_VALUE"""),500.0) -> 500
A9: Income - taxes | E9: Quick View Calculations (Parental Help) | J9: =IFERROR(__xludf.DUMMYFUNCTION("""COMPUTED_VALUE"""),"Insurance") -> Insurance | K9: =IFERROR(__xludf.DUMMYFUNCTION("""COMPUTED_VALUE"""),23.0) -> 23
A10: This includes: paychecks, side jobs, anything that brings money into your bank account. | E10: Income | F10: =G10/12 -> 5575 | G10: =sum(C13:C16) -> 66900 | J10: =IFERROR(__xludf.DUMMYFUNCTION("""COMPUTED_VALUE"""),"Misc") -> Misc | K10: =IFERROR(__xludf.DUMMYFUNCTION("""COMPUTED_VALUE"""),30.0) -> 30
E11: Income (after tax) | F11: =G11/12 -> 4644.4367 | G11: =C34 -> 55733.24 | J11: =IFERROR(__xludf.DUMMYFUNCTION("""COMPUTED_VALUE"""),"Other Services") -> Other Services | K11: =IFERROR(__xludf.DUMMYFUNCTION("""COMPUTED_VALUE"""),18.0) -> 18
A12: * Effective Rate = Average rate across all marginal brackets I fall into | C12: Annual | E12: Needs | F12: =G12/12 -> 2609 | G12: =C68 -> 31308 | J12: =IFERROR(__xludf.DUMMYFUNCTION("""COMPUTED_VALUE"""),"Rent") -> Rent | K12: =IFERROR(__xludf.DUMMYFUNCTION("""COMPUTED_VALUE"""),1327.0) -> 1327
A13: Income Source: Bartending | B13: 5416 ( at $35/hr, 25hr weeks & 48wk years) | C13: 42000 | E13: Wants | F13: =G13/12 -> 815.5 | G13: =C83 -> 9786 | J13: =IFERROR(__xludf.DUMMYFUNCTION("""COMPUTED_VALUE"""),"Shopping") -> Shopping | K13: =IFERROR(__xludf.DUMMYFUNCTION("""COMPUTED_VALUE"""),97.0) -> 97
A14: Income Source: Part-time Freelance Photography | B14: Snappr and Corporate Event shoots estimated $2k per month | C14: 24000 | E14: Left Over | F14: =G14/12 -> 1219.9367 | G14: =C100 -> 14639.24 | J14: =IFERROR(__xludf.DUMMYFUNCTION("""COMPUTED_VALUE"""),"Subscriptions") -> Subscriptions | K14: =IFERROR(__xludf.DUMMYFUNCTION("""COMPUTED_VALUE"""),132.0) -> 132
A15: Income Source: Photography Lessons | B15: (Assuming 1 per month at $75/ea) | C15: 900 | E15: Left Over (w Gov Aid) | F15: =G15/12 -> 1835.9367 | G15: =C101 -> 22031.24 | J15: =IFERROR(__xludf.DUMMYFUNCTION("""COMPUTED_VALUE"""),"Transportation") -> Transportation | K15: =IFERROR(__xludf.DUMMYFUNCTION("""COMPUTED_VALUE"""),25.0) -> 25
A16: Income Source: Baja Montecito? | C16: 0 | E16: Savings (401k, etc) | F16: =G16/12 -> 83.333333 | G16: =C19 -> 1000 | J16: =IFERROR(__xludf.DUMMYFUNCTION("""COMPUTED_VALUE"""),"Travel") -> Travel | K16: =IFERROR(__xludf.DUMMYFUNCTION("""COMPUTED_VALUE"""),142.0) -> 142
A17: Gross Income | C17: =SUM(C13:C16) -> 66900 | E17: 6 Month Reserve (Needs + Wants) | F17: =(F12+F13)*6 -> 20547 | J17: =IFERROR(__xludf.DUMMYFUNCTION("""COMPUTED_VALUE"""),"Utilities") -> Utilities | K17: =IFERROR(__xludf.DUMMYFUNCTION("""COMPUTED_VALUE"""),135.0) -> 135
E18: Total Monthly Budget | F18: =SUM(K2:K23) -> 3074.5
A19: 401k/ IRA Contribution | C19: 1000 | E19: * Left Over includes savings
A20: Freelance 'Above-the-line' Deductions | C20: 0 | E20: self Employment income is taxed differently (so should really be in separate category) See tax Notes Below for Info on 'Above-the-line' Deductions
A21: Federal AGI | B21: (Gross Income - Above-the-Line Deductions -401k/IRA Contr.) | C21: =C17 - SUM(C19:C20) -> 65900
A23: Total Federal Deductibles | C23: =sum(C18:C20) + 15750 -> 16750
A24: Total CA Deductibles | C24: =SUM(C19:C20) + 5706 -> 6706
A25: Federal Taxable Income | B25: Federal AGI – Federal Std Deduction ($15,750) | C25: =C21-15750 -> 50150
A26: California Taxable Income | B26: Federal AGI – CA Std Deduction ($5,706) | C26: =C21-5706 -> 60194
E27: Income/ Rent Note: | F27: Landlords like to see 3/4x Income/ Rent Ratio
A28: Federal Income Tax (Effective Rate) | B28: =(C28/C25) -> 0.12122632 | C28: =IF(C8="Single",IF(C25>609350,(C25-609350)*0.37,0)+IF(C25>243725,MIN(C25-243725,609350-243725)*0.35,0)+IF(C25>191950,MIN(C25-191950,243725-191950)*0.32,0)+IF(C25>100525,MIN(C25-100525,191950-100525)*0.24,0)+IF(C25>47150,MIN(C25-47150,100525-47150)*0.22,0)+IF(C25>11925,MIN(C25-11925,47150-11925)*0.12,0)+IF(C25>0,MIN(C25,11925)*0.1,0),0) -> 6079.5 | E28: $65k gross income | F28: Monthly gross is about $5,417
A29: California State Tax (Effective Rate) | B29: =(C29/C26) -> 0.03113699 | C29: =IF(C8="Single",LET(caIncome,C26-5202,IF(caIncome>677275,(caIncome-677275)*0.133,0)+IF(caIncome>406364,MIN(caIncome-406364,677275-406364)*0.123,0)+IF(caIncome>338639,MIN(caIncome-338639,406364-338639)*0.113,0)+IF(caIncome>68350,MIN(caIncome-68350,338639-68350)*0.093,0)+IF(caIncome>54081,MIN(caIncome-54081,68350-54081)*0.08,0)+IF(caIncome>38959,MIN(caIncome-38959,54081-38959)*0.06,0)+IF(caIncome>27490,MIN(caIncome-27490,38959-27490)*0.04,0)+IF(caIncome>11450,MIN(caIncome-11450,27490-11450)*0.02,0)+IF(caIncome>0,MIN(caIncome,11450)*0.01,0)),0) -> 1874.26 | E29: 3x rent: | F29: 1800
A30: Social Security (6.2%) | B30: 0.062 | C30: =MIN(C13,176100)*0.062 -> 2604 | E30: 4x rent: | F30: 1350
A31: Medicare (1.45%) | B31: 0.0145 | C31: =C13*0.0145 -> 609
B32: 0
A33: TOTAL TAXES | B33: =sum(B28:B31) -> 0.22886331 | C33: =sum(C28:C31) -> 11166.76
A34: TOTAL AFTER TAXES | B34: =C34/12 -> 4644.4367 | C34: =sum(C13:C16) - C33 -> 55733.24
A36: Must-Have Expenses
A37: This includes: Rent, utilities, cell phone bills, anything that will incur late fees. Includes other essentials like groceries and automatic savings account deductions. Saving is a must! | C37: Notes:
A38: Rent or Mortgage | B38: 1327 | C38: lowest rent for SF 3 person app ~ $1.4k | D38: Rent
A39: Utilities | B39: 85 | C39: Wifi: $25, Gas & Electric: 30-60 (Dont pay water + garbage) | D39: Utilities
A40: Monthly cleaning | B40: 50 | C40: $200 cleaning monthly | D40: Utilities
A41: Renters Insurance | C41: (Based on GPT estimate of $20-30/mo) ($300/yr) - Dont think we're paying this at Russian hill | D41: Rent
C42: Housing Total: = $1462
...

Sheet All Transactions
A1: =IFERROR(__xludf.DUMMYFUNCTION("ARRAYFORMULA({ {""Transaction Date"",""Description"",""Amount"",""Budget Category"",""Source""}; { TO_DATE(FILTER('Capitol One Transactions'!A2:A1000, ('Capitol One Transactions'!A2:A1000<>"""") * ('Capitol One Transactions'!D2:D1000<>""Descrip"&"tion""))), FILTER('Capitol One Transactions'!D2:D1000, ('Capitol One Transactions'!A2:A1000<>"""") * ('Capitol One Transactions'!D2:D1000<>""Description"")), -ABS(VALUE(FILTER('Capitol One Transactions'!F2:F1000, ('Capitol One Transactions'!A2:A10"&"00<>"""") * ('Capitol One Transactions'!D2:D1000<>""Description"")))), FILTER('Capitol One Transactions'!G2:G1000, ('Capitol One Transactions'!A2:A1000<>"""") * ('Capitol One Transactions'!D2:D1000<>""Description"")), IF(FILTER('Capitol One Transa"&"ctions'!A2:A1000, ('Capitol One Transactions'!A2:A1000<>"""") * ('Capitol One Transactions'!D2:D1000<>""Description""))<>"""",""Capital One"","""") }; { TO_DATE(INT(FILTER('Venmo Transactions'!A20:A1000, 'Venmo Transactions'!A20:A1000<>""""))),"&" FILTER('Venmo Transactions'!D20:D1000, 'Venmo Transactions'!A20:A1000<>""""), FILTER('Venmo Transactions'!G20:G1000, 'Venmo Transactions'!A20:A1000<>""""), IFERROR(FILTER('Venmo Transactions'!H20:H1000, 'Venmo Transactions'!A20:A1000<>""""),"&"""Misc""), IF(FILTER('Venmo Transactions'!A20:A1000, 'Venmo Transactions'!A20:A1000<>"""")<>"""",""Venmo"","""") }; { TO_DATE(FILTER('Other Transactions'!A2:A1000, 'Other Transactions'!A2:A1000<>"""")), FILTER('Other Transactions'!B2:B1"&"000, 'Other Transactions'!A2:A1000<>""""), FILTER('Other Transactions'!C2:C1000, 'Other Transactions'!A2:A1000<>""""), FILTER('Other Transactions'!D2:D1000, 'Other Transactions'!A2:A1000<>""""), FILTER('Other Transactions'!E2:E1000, 'Other Tra"&"nsactions'!A2:A1000<>"""") } })"),"Transaction Date") -> Transaction Date | B1: =IFERROR(__xludf.DUMMYFUNCTION("""COMPUTED_VALUE"""),"Description") -> Description | C1: =IFERROR(__xludf.DUMMYFUNCTION("""COMPUTED_VALUE"""),"Amount") -> Amount | D1: =IFERROR(__xludf.DUMMYFUNCTION("""COMPUTED_VALUE"""),"Budget Category") -> Budget Category | E1: =IFERROR(__xludf.DUMMYFUNCTION("""COMPUTED_VALUE"""),"Source") -> Source | F1: Budget Amount
A2: =IFERROR(__xludf.DUMMYFUNCTION("""COMPUTED_VALUE"""),46111.0) -> 46111 | B2: =IFERROR(__xludf.DUMMYFUNCTION("""COMPUTED_VALUE"""),"TST*SIGHTGLASS COFFEE -") -> TST*SIGHTGLASS COFFEE - | C2: =IFERROR(__xludf.DUMMYFUNCTION("""COMPUTED_VALUE"""),-5.83) -> -5.83 | D2: =IFERROR(__xludf.DUMMYFUNCTION("""COMPUTED_VALUE"""),"Coffee") -> Coffee | E2: =IFERROR(__xludf.DUMMYFUNCTION("""COMPUTED_VALUE"""),"Capital One") -> Capital One | F2: {=IF(D2:D1000="","", IFERROR(VLOOKUP(D2:D1000,'Living Expenses'!J:K,2,FALSE),0) )} -> 84
A3: =IFERROR(__xludf.DUMMYFUNCTION("""COMPUTED_VALUE"""),46111.0) -> 46111 | B3: =IFERROR(__xludf.DUMMYFUNCTION("""COMPUTED_VALUE"""),"IKEA SAN FRAN") -> IKEA SAN FRAN | C3: =IFERROR(__xludf.DUMMYFUNCTION("""COMPUTED_VALUE"""),-21.67) -> -21.67 | D3: =IFERROR(__xludf.DUMMYFUNCTION("""COMPUTED_VALUE"""),"Shopping") -> Shopping | E3: =IFERROR(__xludf.DUMMYFUNCTION("""COMPUTED_VALUE"""),"Capital One") -> Capital One | F3: 97
A4: =IFERROR(__xludf.DUMMYFUNCTION("""COMPUTED_VALUE"""),46110.0) -> 46110 | B4: =IFERROR(__xludf.DUMMYFUNCTION("""COMPUTED_VALUE"""),"CLIPPER TRANSIT FARE") -> CLIPPER TRANSIT FARE | C4: =IFERROR(__xludf.DUMMYFUNCTION("""COMPUTED_VALUE"""),-2.85) -> -2.85 | D4: =IFERROR(__xludf.DUMMYFUNCTION("""COMPUTED_VALUE"""),"Transportation") -> Transportation | E4: =IFERROR(__xludf.DUMMYFUNCTION("""COMPUTED_VALUE"""),"Capital One") -> Capital One | F4: 25
A5: =IFERROR(__xludf.DUMMYFUNCTION("""COMPUTED_VALUE"""),46111.0) -> 46111 | B5: =IFERROR(__xludf.DUMMYFUNCTION("""COMPUTED_VALUE"""),"SPIN* PENDING.BIRD.CO") -> SPIN* PENDING.BIRD.CO | C5: =IFERROR(__xludf.DUMMYFUNCTION("""COMPUTED_VALUE"""),-5.22) -> -5.22 | D5: =IFERROR(__xludf.DUMMYFUNCTION("""COMPUTED_VALUE"""),"Transportation") -> Transportation | E5: =IFERROR(__xludf.DUMMYFUNCTION("""COMPUTED_VALUE"""),"Capital One") -> Capital One | F5: 25
A6: =IFERROR(__xludf.DUMMYFUNCTION("""COMPUTED_VALUE"""),46111.0) -> 46111 | B6: =IFERROR(__xludf.DUMMYFUNCTION("""COMPUTED_VALUE"""),"THUMBTACK 9443567618") -> THUMBTACK 9443567618 | C6: =IFERROR(__xludf.DUMMYFUNCTION("""COMPUTED_VALUE"""),-24.46) -> -24.46 | D6: =IFERROR(__xludf.DUMMYFUNCTION("""COMPUTED_VALUE"""),"Business Expenses") -> Business Expenses | E6: =IFERROR(__xludf.DUMMYFUNCTION("""COMPUTED_VALUE"""),"Capital One") -> Capital One | F6: 84
A7: =IFERROR(__xludf.DUMMYFUNCTION("""COMPUTED_VALUE"""),46109.0) -> 46109 | B7: =IFERROR(__xludf.DUMMYFUNCTION("""COMPUTED_VALUE"""),"CAMPUS") -> CAMPUS | C7: =IFERROR(__xludf.DUMMYFUNCTION("""COMPUTED_VALUE"""),-33.79) -> -33.79 | D7: =IFERROR(__xludf.DUMMYFUNCTION("""COMPUTED_VALUE"""),"Bar/ Alcohol") -> Bar/ Alcohol | E7: =IFERROR(__xludf.DUMMYFUNCTION("""COMPUTED_VALUE"""),"Capital One") -> Capital One | F7: 100
A8: =IFERROR(__xludf.DUMMYFUNCTION("""COMPUTED_VALUE"""),46110.0) -> 46110 | B8: =IFERROR(__xludf.DUMMYFUNCTION("""COMPUTED_VALUE"""),"TRUST THE UNIVERSE") -> TRUST THE UNIVERSE | C8: =IFERROR(__xludf.DUMMYFUNCTION("""COMPUTED_VALUE"""),-68.0) -> -68 | D8: =IFERROR(__xludf.DUMMYFUNCTION("""COMPUTED_VALUE"""),"Entertainment") -> Entertainment | E8: =IFERROR(__xludf.DUMMYFUNCTION("""COMPUTED_VALUE"""),"Capital One") -> Capital One | F8: 47.5
A9: =IFERROR(__xludf.DUMMYFUNCTION("""COMPUTED_VALUE"""),46109.0) -> 46109 | B9: =IFERROR(__xludf.DUMMYFUNCTION("""COMPUTED_VALUE"""),"PAYPAL *UBER") -> PAYPAL *UBER | C9: =IFERROR(__xludf.DUMMYFUNCTION("""COMPUTED_VALUE"""),-10.91) -> -10.91 | D9: =IFERROR(__xludf.DUMMYFUNCTION("""COMPUTED_VALUE"""),"Transportation") -> Transportation | E9: =IFERROR(__xludf.DUMMYFUNCTION("""COMPUTED_VALUE"""),"Capital One") -> Capital One | F9: 25
A10: =IFERROR(__xludf.DUMMYFUNCTION("""COMPUTED_VALUE"""),46108.0) -> 46108 | B10: =IFERROR(__xludf.DUMMYFUNCTION("""COMPUTED_VALUE"""),"CLIPPER TRANSIT FARE") -> CLIPPER TRANSIT FARE | C10: =IFERROR(__xludf.DUMMYFUNCTION("""COMPUTED_VALUE"""),-2.85) -> -2.85 | D10: =IFERROR(__xludf.DUMMYFUNCTION("""COMPUTED_VALUE"""),"Transportation") -> Transportation | E10: =IFERROR(__xludf.DUMMYFUNCTION("""COMPUTED_VALUE"""),"Capital One") -> Capital One | F10: 25
A11: =IFERROR(__xludf.DUMMYFUNCTION("""COMPUTED_VALUE"""),46108.0) -> 46108 | B11: =IFERROR(__xludf.DUMMYFUNCTION("""COMPUTED_VALUE"""),"MR LIQUOR NORTH POINT") -> MR LIQUOR NORTH POINT | C11: =IFERROR(__xludf.DUMMYFUNCTION("""COMPUTED_VALUE"""),-11.94) -> -11.94 | D11: =IFERROR(__xludf.DUMMYFUNCTION("""COMPUTED_VALUE"""),"Bar/ Alcohol") -> Bar/ Alcohol | E11: =IFERROR(__xludf.DUMMYFUNCTION("""COMPUTED_VALUE"""),"Capital One") -> Capital One | F11: 100
A12: =IFERROR(__xludf.DUMMYFUNCTION("""COMPUTED_VALUE"""),46108.0) -> 46108 | B12: =IFERROR(__xludf.DUMMYFUNCTION("""COMPUTED_VALUE"""),"Adobe Inc") -> Adobe Inc | C12: =IFERROR(__xludf.DUMMYFUNCTION("""COMPUTED_VALUE"""),-39.99) -> -39.99 | D12: =IFERROR(__xludf.DUMMYFUNCTION("""COMPUTED_VALUE"""),"Subscriptions") -> Subscriptions | E12: =IFERROR(__xludf.DUMMYFUNCTION("""COMPUTED_VALUE"""),"Capital One") -> Capital One | F12: 132
A13: =IFERROR(__xludf.DUMMYFUNCTION("""COMPUTED_VALUE"""),46108.0) -> 46108 | B13: =IFERROR(__xludf.DUMMYFUNCTION("""COMPUTED_VALUE"""),"TESLA, INC.") -> TESLA, INC. | C13: =IFERROR(__xludf.DUMMYFUNCTION("""COMPUTED_VALUE"""),-7.95) -> -7.95 | D13: =IFERROR(__xludf.DUMMYFUNCTION("""COMPUTED_VALUE"""),"Transportation") -> Transportation | E13: =IFERROR(__xludf.DUMMYFUNCTION("""COMPUTED_VALUE"""),"Capital One") -> Capital One | F13: 25
A14: =IFERROR(__xludf.DUMMYFUNCTION("""COMPUTED_VALUE"""),46107.0) -> 46107 | B14: =IFERROR(__xludf.DUMMYFUNCTION("""COMPUTED_VALUE"""),"WALGREENS #5599") -> WALGREENS #5599 | C14: =IFERROR(__xludf.DUMMYFUNCTION("""COMPUTED_VALUE"""),-26.51) -> -26.51 | D14: =IFERROR(__xludf.DUMMYFUNCTION("""COMPUTED_VALUE"""),"Misc") -> Misc | E14: =IFERROR(__xludf.DUMMYFUNCTION("""COMPUTED_VALUE"""),"Capital One") -> Capital One | F14: 30
A15: =IFERROR(__xludf.DUMMYFUNCTION("""COMPUTED_VALUE"""),46105.0) -> 46105 | B15: =IFERROR(__xludf.DUMMYFUNCTION("""COMPUTED_VALUE"""),"SQ *CAFE #27255 UNION SQU") -> SQ *CAFE #27255 UNION SQU | C15: =IFERROR(__xludf.DUMMYFUNCTION("""COMPUTED_VALUE"""),-6.75) -> -6.75 | D15: =IFERROR(__xludf.DUMMYFUNCTION("""COMPUTED_VALUE"""),"Dining") -> Dining | E15: =IFERROR(__xludf.DUMMYFUNCTION("""COMPUTED_VALUE"""),"Capital One") -> Capital One | F15: 320
A16: =IFERROR(__xludf.DUMMYFUNCTION("""COMPUTED_VALUE"""),46104.0) -> 46104 | B16: =IFERROR(__xludf.DUMMYFUNCTION("""COMPUTED_VALUE"""),"THUMBTACK 9443567618") -> THUMBTACK 9443567618 | C16: =IFERROR(__xludf.DUMMYFUNCTION("""COMPUTED_VALUE"""),-32.34) -> -32.34 | D16: =IFERROR(__xludf.DUMMYFUNCTION("""COMPUTED_VALUE"""),"Business Expenses") -> Business Expenses | E16: =IFERROR(__xludf.DUMMYFUNCTION("""COMPUTED_VALUE"""),"Capital One") -> Capital One | F16: 84
A17: =IFERROR(__xludf.DUMMYFUNCTION("""COMPUTED_VALUE"""),46104.0) -> 46104 | B17: =IFERROR(__xludf.DUMMYFUNCTION("""COMPUTED_VALUE"""),"BI-RITE MARKET") -> BI-RITE MARKET | C17: =IFERROR(__xludf.DUMMYFUNCTION("""COMPUTED_VALUE"""),-11.96) -> -11.96 | D17: =IFERROR(__xludf.DUMMYFUNCTION("""COMPUTED_VALUE"""),"Shopping") -> Shopping | E17: =IFERROR(__xludf.DUMMYFUNCTION("""COMPUTED_VALUE"""),"Capital One") -> Capital One | F17: 97
A18: =IFERROR(__xludf.DUMMYFUNCTION("""COMPUTED_VALUE"""),46105.0) -> 46105 | B18: =IFERROR(__xludf.DUMMYFUNCTION("""COMPUTED_VALUE"""),"Google One") -> Google One | C18: =IFERROR(__xludf.DUMMYFUNCTION("""COMPUTED_VALUE"""),-9.99) -> -9.99 | D18: =IFERROR(__xludf.DUMMYFUNCTION("""COMPUTED_VALUE"""),"Entertainment") -> Entertainment | E18: =IFERROR(__xludf.DUMMYFUNCTION("""COMPUTED_VALUE"""),"Capital One") -> Capital One | F18: 47.5
A19: =IFERROR(__xludf.DUMMYFUNCTION("""COMPUTED_VALUE"""),46103.0) -> 46103 | B19: =IFERROR(__xludf.DUMMYFUNCTION("""COMPUTED_VALUE"""),"POLK STREET MARKET") -> POLK STREET MARKET | C19: =IFERROR(__xludf.DUMMYFUNCTION("""COMPUTED_VALUE"""),-19.16) -> -19.16 | D19: =IFERROR(__xludf.DUMMYFUNCTION("""COMPUTED_VALUE"""),"Shopping") -> Shopping | E19: =IFERROR(__xludf.DUMMYFUNCTION("""COMPUTED_VALUE"""),"Capital One") -> Capital One | F19: 97
A20: =IFERROR(__xludf.DUMMYFUNCTION("""COMPUTED_VALUE"""),46103.0) -> 46103 | B20: =IFERROR(__xludf.DUMMYFUNCTION("""COMPUTED_VALUE"""),"THUMBTACK 9443567618") -> THUMBTACK 9443567618 | C20: =IFERROR(__xludf.DUMMYFUNCTION("""COMPUTED_VALUE"""),-17.66) -> -17.66 | D20: =IFERROR(__xludf.DUMMYFUNCTION("""COMPUTED_VALUE"""),"Business Expenses") -> Business Expenses | E20: =IFERROR(__xludf.DUMMYFUNCTION("""COMPUTED_VALUE"""),"Capital One") -> Capital One | F20: 84
A21: =IFERROR(__xludf.DUMMYFUNCTION("""COMPUTED_VALUE"""),46103.0) -> 46103 | B21: =IFERROR(__xludf.DUMMYFUNCTION("""COMPUTED_VALUE"""),"COLE HARDWARE") -> COLE HARDWARE | C21: =IFERROR(__xludf.DUMMYFUNCTION("""COMPUTED_VALUE"""),-17.77) -> -17.77 | D21: =IFERROR(__xludf.DUMMYFUNCTION("""COMPUTED_VALUE"""),"Shopping") -> Shopping | E21: =IFERROR(__xludf.DUMMYFUNCTION("""COMPUTED_VALUE"""),"Capital One") -> Capital One | F21: 97
A22: =IFERROR(__xludf.DUMMYFUNCTION("""COMPUTED_VALUE"""),46103.0) -> 46103 | B22: =IFERROR(__xludf.DUMMYFUNCTION("""COMPUTED_VALUE"""),"SQ *PHILZ COFFEE") -> SQ *PHILZ COFFEE | C22: =IFERROR(__xludf.DUMMYFUNCTION("""COMPUTED_VALUE"""),-6.6) -> -6.6 | D22: =IFERROR(__xludf.DUMMYFUNCTION("""COMPUTED_VALUE"""),"Coffee") -> Coffee | E22: =IFERROR(__xludf.DUMMYFUNCTION("""COMPUTED_VALUE"""),"Capital One") -> Capital One | F22: 84
A23: =IFERROR(__xludf.DUMMYFUNCTION("""COMPUTED_VALUE"""),46100.0) -> 46100 | B23: =IFERROR(__xludf.DUMMYFUNCTION("""COMPUTED_VALUE"""),"TST*HAYES VALLEY BAKEWOR") -> TST*HAYES VALLEY BAKEWOR | C23: =IFERROR(__xludf.DUMMYFUNCTION("""COMPUTED_VALUE"""),-5.75) -> -5.75 | D23: =IFERROR(__xludf.DUMMYFUNCTION("""COMPUTED_VALUE"""),"Dining") -> Dining | E23: =IFERROR(__xludf.DUMMYFUNCTION("""COMPUTED_VALUE"""),"Capital One") -> Capital One | F23: 320
A24: =IFERROR(__xludf.DUMMYFUNCTION("""COMPUTED_VALUE"""),46101.0) -> 46101 | B24: =IFERROR(__xludf.DUMMYFUNCTION("""COMPUTED_VALUE"""),"HOSTINGER* HOSTINGER.C") -> HOSTINGER* HOSTINGER.C | C24: =IFERROR(__xludf.DUMMYFUNCTION("""COMPUTED_VALUE"""),-17.99) -> -17.99 | D24: =IFERROR(__xludf.DUMMYFUNCTION("""COMPUTED_VALUE"""),"Internet") -> Internet | E24: =IFERROR(__xludf.DUMMYFUNCTION("""COMPUTED_VALUE"""),"Capital One") -> Capital One | F24: 0
A25: =IFERROR(__xludf.DUMMYFUNCTION("""COMPUTED_VALUE"""),46100.0) -> 46100 | B25: =IFERROR(__xludf.DUMMYFUNCTION("""COMPUTED_VALUE"""),"AMAZON MKTPL*BD8E23Z50") -> AMAZON MKTPL*BD8E23Z50 | C25: =IFERROR(__xludf.DUMMYFUNCTION("""COMPUTED_VALUE"""),-75.95) -> -75.95 | D25: =IFERROR(__xludf.DUMMYFUNCTION("""COMPUTED_VALUE"""),"Shopping") -> Shopping | E25: =IFERROR(__xludf.DUMMYFUNCTION("""COMPUTED_VALUE"""),"Capital One") -> Capital One | F25: 97
A26: =IFERROR(__xludf.DUMMYFUNCTION("""COMPUTED_VALUE"""),46099.0) -> 46099 | B26: =IFERROR(__xludf.DUMMYFUNCTION("""COMPUTED_VALUE"""),"SQ *SAINT FRANK COFFEE") -> SQ *SAINT FRANK COFFEE | C26: =IFERROR(__xludf.DUMMYFUNCTION("""COMPUTED_VALUE"""),-6.25) -> -6.25 | D26: =IFERROR(__xludf.DUMMYFUNCTION("""COMPUTED_VALUE"""),"Coffee") -> Coffee | E26: =IFERROR(__xludf.DUMMYFUNCTION("""COMPUTED_VALUE"""),"Capital One") -> Capital One | F26: 84
A27: =IFERROR(__xludf.DUMMYFUNCTION("""COMPUTED_VALUE"""),46099.0) -> 46099 | B27: =IFERROR(__xludf.DUMMYFUNCTION("""COMPUTED_VALUE"""),"BAYWHEE*1 RIDE") -> BAYWHEE*1 RIDE | C27: =IFERROR(__xludf.DUMMYFUNCTION("""COMPUTED_VALUE"""),-9.59) -> -9.59 | D27: =IFERROR(__xludf.DUMMYFUNCTION("""COMPUTED_VALUE"""),"Transportation") -> Transportation | E27: =IFERROR(__xludf.DUMMYFUNCTION("""COMPUTED_VALUE"""),"Capital One") -> Capital One | F27: 25
A28: =IFERROR(__xludf.DUMMYFUNCTION("""COMPUTED_VALUE"""),46098.0) -> 46098 | B28: =IFERROR(__xludf.DUMMYFUNCTION("""COMPUTED_VALUE"""),"LEBEAU NOB HILL MARKET") -> LEBEAU NOB HILL MARKET | C28: =IFERROR(__xludf.DUMMYFUNCTION("""COMPUTED_VALUE"""),-13.84) -> -13.84 | D28: =IFERROR(__xludf.DUMMYFUNCTION("""COMPUTED_VALUE"""),"Shopping") -> Shopping | E28: =IFERROR(__xludf.DUMMYFUNCTION("""COMPUTED_VALUE"""),"Capital One") -> Capital One | F28: 97
A29: =IFERROR(__xludf.DUMMYFUNCTION("""COMPUTED_VALUE"""),46098.0) -> 46098 | B29: =IFERROR(__xludf.DUMMYFUNCTION("""COMPUTED_VALUE"""),"CLIPPER TRANSIT FARE") -> CLIPPER TRANSIT FARE | C29: =IFERROR(__xludf.DUMMYFUNCTION("""COMPUTED_VALUE"""),-2.55) -> -2.55 | D29: =IFERROR(__xludf.DUMMYFUNCTION("""COMPUTED_VALUE"""),"Transportation") -> Transportation | E29: =IFERROR(__xludf.DUMMYFUNCTION("""COMPUTED_VALUE"""),"Capital One") -> Capital One | F29: 25
A30: =IFERROR(__xludf.DUMMYFUNCTION("""COMPUTED_VALUE"""),46098.0) -> 46098 | B30: =IFERROR(__xludf.DUMMYFUNCTION("""COMPUTED_VALUE"""),"AMAZON MKTPL*BP5GQ5UA0") -> AMAZON MKTPL*BP5GQ5UA0 | C30: =IFERROR(__xludf.DUMMYFUNCTION("""COMPUTED_VALUE"""),-44.83) -> -44.83 | D30: =IFERROR(__xludf.DUMMYFUNCTION("""COMPUTED_VALUE"""),"Shopping") -> Shopping | E30: =IFERROR(__xludf.DUMMYFUNCTION("""COMPUTED_VALUE"""),"Capital One") -> Capital One | F30: 97
A31: =IFERROR(__xludf.DUMMYFUNCTION("""COMPUTED_VALUE"""),46097.0) -> 46097 | B31: =IFERROR(__xludf.DUMMYFUNCTION("""COMPUTED_VALUE"""),"AMAZON PRIME*9N4U39UX3") -> AMAZON PRIME*9N4U39UX3 | C31: =IFERROR(__xludf.DUMMYFUNCTION("""COMPUTED_VALUE"""),-1.08) -> -1.08 | D31: =IFERROR(__xludf.DUMMYFUNCTION("""COMPUTED_VALUE"""),"Shopping") -> Shopping | E31: =IFERROR(__xludf.DUMMYFUNCTION("""COMPUTED_VALUE"""),"Capital One") -> Capital One | F31: 97
A32: =IFERROR(__xludf.DUMMYFUNCTION("""COMPUTED_VALUE"""),46096.0) -> 46096 | B32: =IFERROR(__xludf.DUMMYFUNCTION("""COMPUTED_VALUE"""),"USPS CHANGE OF ADDRESS") -> USPS CHANGE OF ADDRESS | C32: =IFERROR(__xludf.DUMMYFUNCTION("""COMPUTED_VALUE"""),-1.25) -> -1.25 | D32: =IFERROR(__xludf.DUMMYFUNCTION("""COMPUTED_VALUE"""),"Other Services") -> Other Services | E32: =IFERROR(__xludf.DUMMYFUNCTION("""COMPUTED_VALUE"""),"Capital One") -> Capital One | F32: 18
A33: =IFERROR(__xludf.DUMMYFUNCTION("""COMPUTED_VALUE"""),46096.0) -> 46096 | B33: =IFERROR(__xludf.DUMMYFUNCTION("""COMPUTED_VALUE"""),"TARGET 00027664") -> TARGET 00027664 | C33: =IFERROR(__xludf.DUMMYFUNCTION("""COMPUTED_VALUE"""),-244.15) -> -244.15 | D33: =IFERROR(__xludf.DUMMYFUNCTION("""COMPUTED_VALUE"""),"Shopping") -> Shopping | E33: =IFERROR(__xludf.DUMMYFUNCTION("""COMPUTED_VALUE"""),"Capital One") -> Capital One | F33: 97
A34: =IFERROR(__xludf.DUMMYFUNCTION("""COMPUTED_VALUE"""),46096.0) -> 46096 | B34: =IFERROR(__xludf.DUMMYFUNCTION("""COMPUTED_VALUE"""),"APPLE.COM/BILL") -> APPLE.COM/BILL | C34: =IFERROR(__xludf.DUMMYFUNCTION("""COMPUTED_VALUE"""),-2.99) -> -2.99 | D34: =IFERROR(__xludf.DUMMYFUNCTION("""COMPUTED_VALUE"""),"Entertainment") -> Entertainment | E34: =IFERROR(__xludf.DUMMYFUNCTION("""COMPUTED_VALUE"""),"Capital One") -> Capital One | F34: 47.5
A35: =IFERROR(__xludf.DUMMYFUNCTION("""COMPUTED_VALUE"""),46096.0) -> 46096 | B35: =IFERROR(__xludf.DUMMYFUNCTION("""COMPUTED_VALUE"""),"TST* SUPER DUPER BURGERS") -> TST* SUPER DUPER BURGERS | C35: =IFERROR(__xludf.DUMMYFUNCTION("""COMPUTED_VALUE"""),-17.08) -> -17.08 | D35: =IFERROR(__xludf.DUMMYFUNCTION("""COMPUTED_VALUE"""),"Dining") -> Dining | E35: =IFERROR(__xludf.DUMMYFUNCTION("""COMPUTED_VALUE"""),"Capital One") -> Capital One | F35: 320
A36: =IFERROR(__xludf.DUMMYFUNCTION("""COMPUTED_VALUE"""),46095.0) -> 46095 | B36: =IFERROR(__xludf.DUMMYFUNCTION("""COMPUTED_VALUE"""),"LIME*RIDE 4G6N") -> LIME*RIDE 4G6N | C36: =IFERROR(__xludf.DUMMYFUNCTION("""COMPUTED_VALUE"""),-7.58) -> -7.58 | D36: =IFERROR(__xludf.DUMMYFUNCTION("""COMPUTED_VALUE"""),"Entertainment") -> Entertainment | E36: =IFERROR(__xludf.DUMMYFUNCTION("""COMPUTED_VALUE"""),"Capital One") -> Capital One | F36: 47.5
A37: =IFERROR(__xludf.DUMMYFUNCTION("""COMPUTED_VALUE"""),46094.0) -> 46094 | B37: =IFERROR(__xludf.DUMMYFUNCTION("""COMPUTED_VALUE"""),"LEBEAU NOB HILL MARKET") -> LEBEAU NOB HILL MARKET | C37: =IFERROR(__xludf.DUMMYFUNCTION("""COMPUTED_VALUE"""),-9.75) -> -9.75 | D37: =IFERROR(__xludf.DUMMYFUNCTION("""COMPUTED_VALUE"""),"Groceries") -> Groceries | E37: =IFERROR(__xludf.DUMMYFUNCTION("""COMPUTED_VALUE"""),"Capital One") -> Capital One | F37: 500
A38: =IFERROR(__xludf.DUMMYFUNCTION("""COMPUTED_VALUE"""),46093.0) -> 46093 | B38: =IFERROR(__xludf.DUMMYFUNCTION("""COMPUTED_VALUE"""),"SEETICKET* HIPPIE SA") -> SEETICKET* HIPPIE SA | C38: =IFERROR(__xludf.DUMMYFUNCTION("""COMPUTED_VALUE"""),-74.44) -> -74.44 | D38: =IFERROR(__xludf.DUMMYFUNCTION("""COMPUTED_VALUE"""),"Entertainment") -> Entertainment | E38: =IFERROR(__xludf.DUMMYFUNCTION("""COMPUTED_VALUE"""),"Capital One") -> Capital One | F38: 47.5
A39: =IFERROR(__xludf.DUMMYFUNCTION("""COMPUTED_VALUE"""),46091.0) -> 46091 | B39: =IFERROR(__xludf.DUMMYFUNCTION("""COMPUTED_VALUE"""),"SHELL OIL 57444215909") -> SHELL OIL 57444215909 | C39: =IFERROR(__xludf.DUMMYFUNCTION("""COMPUTED_VALUE"""),-24.94) -> -24.94 | D39: =IFERROR(__xludf.DUMMYFUNCTION("""COMPUTED_VALUE"""),"Gas/Automotive") -> Gas/Automotive | E39: =IFERROR(__xludf.DUMMYFUNCTION("""COMPUTED_VALUE"""),"Capital One") -> Capital One | F39: 0
A40: =IFERROR(__xludf.DUMMYFUNCTION("""COMPUTED_VALUE"""),46092.0) -> 46092 | B40: =IFERROR(__xludf.DUMMYFUNCTION("""COMPUTED_VALUE"""),"COLE HARDWARE") -> COLE HARDWARE | C40: =IFERROR(__xludf.DUMMYFUNCTION("""COMPUTED_VALUE"""),-32.04) -> -32.04 | D40: =IFERROR(__xludf.DUMMYFUNCTION("""COMPUTED_VALUE"""),"Shopping") -> Shopping | E40: =IFERROR(__xludf.DUMMYFUNCTION("""COMPUTED_VALUE"""),"Capital One") -> Capital One | F40: 97
...

Sheet Summary 2026
A1: Year: | B1: 2026
A2: Total | B2: =SUM(B4:B22) -> 3074.5 | C2: =SUM(C4:C22) -> 0 | D2: =SUM(D4:D22) -> 3074.5 | E2: =SUM(E4:E22) -> 0 | F2: =SUM(F4:F22) -> 3074.5 | G2: =SUM(G4:G22) -> 3104.83 | H2: =SUM(H4:H22) -> -30.33 | I2: =SUM(I4:I22) -> 2882.46 | ... Z2: =SUM(Z4:Z22) -> 3074.5
A3: Category | B3: Budget | C3: Jan Spend | D3: Jan Diff | E3: Feb Spend | F3: Feb Diff | G3: Mar Spend | H3: Mar Diff | I3: April Spend | J3: April Diff | K3: May Spend | L3: May Diff | M3: June Spend | N3: June Diff | O3: July Spend | P3: July Diff | Q3: Aug Spend | R3: Aug Diff | S3: Sep Spend | T3: Sep Diff | U3: Oct Spend | V3: Oct Diff | W3: Nov Spend | X3: Nov Diff | Y3: Dec Spend | Z3: Dec Diff
A4: =IFERROR(__xludf.DUMMYFUNCTION("SORT(UNIQUE(FILTER('Living Expenses'!J2:J1001,'Living Expenses'!J2:J1001<>"""")))"),"AI Fees") -> AI Fees | B4: =IFERROR(VLOOKUP(A4,'Living Expenses'!J:K,2,FALSE),0) -> 10 | C4: {=IF(A4:A1001="",, IFERROR(ABS(SUMIFS( 'All Transactions'!C:C, 'All Transactions'!D:D, A4:A1001, 'All Transactions'!A:A, ">="&DATE($B$1,1,1), 'All Transactions'!A:A, "<"&DATE($B$1,2,1) )),0))} -> 0 | D4: =B4 - C4 -> 10 | E4: {=IF(A4:A1001="",, IFERROR(ABS(SUMIFS( 'All Transactions'!C:C, 'All Transactions'!D:D, A4:A1001, 'All Transactions'!A:A, ">="&DATE($B$1,2,1), 'All Transactions'!A:A, "<"&DATE($B$1,3,1) )),0))} -> 0 | F4: =B4 - E4 -> 10 | G4: {=MAP(A4:A1001, LAMBDA(cat, IF(cat="","", IFERROR(ABS(SUMIFS( 'All Transactions'!C:C, 'All Transactions'!D:D, cat, 'All Transactions'!A:A, ">="&DATE($B$1,3,1), 'All Transactions'!A:A, "<"&DATE($B$1,4,1) )),0) )))} -> 2.03 | H4: =B4 - G4 -> 7.97 | I4: {=MAP(A4:A1001, LAMBDA(cat, IF(cat="","", IFERROR(ABS(SUMIFS( 'All Transactions'!C:C, 'All Transactions'!D:D, cat, 'All Transactions'!A:A, ">="&DATE($B$1,4,1), 'All Transactions'!A:A, "<"&DATE($B$1,5,1) )),0) )))} -> 0 | J4: =B4 - I4 -> 10 | K4: {=MAP(A4:A1001, LAMBDA(cat, IF(cat="","", IFERROR(ABS(SUMIFS( 'All Transactions'!C:C, 'All Transactions'!D:D, cat, 'All Transactions'!A:A, ">="&DATE($B$1,5,1), 'All Transactions'!A:A, "<"&DATE($B$1,6,1) )),0) )))} -> 0 | L4: =B4 - K4 -> 10 | M4: {=MAP(A4:A1001, LAMBDA(cat, IF(cat="","", IFERROR(ABS(SUMIFS( 'All Transactions'!C:C, 'All Transactions'!D:D, cat, 'All Transactions'!A:A, ">="&DATE($B$1,6,1), 'All Transactions'!A:A, "<"&DATE($B$1,7,1) )),0) )))} -> 0 | N4: =B4 - M4 -> 10 | O4: {=MAP(A4:A1001, LAMBDA(cat, IF(cat="","", IFERROR(ABS(SUMIFS( 'All Transactions'!C:C, 'All Transactions'!D:D, cat, 'All Transactions'!A:A, ">="&DATE($B$1,7,1), 'All Transactions'!A:A, "<"&DATE($B$1,8,1) )),0) )))} -> 0 | P4: =B4 - O4 -> 10 | Q4: {=MAP(A4:A1001, LAMBDA(cat, IF(cat="","", IFERROR(ABS(SUMIFS( 'All Transactions'!C:C, 'All Transactions'!D:D, cat, 'All Transactions'!A:A, ">="&DATE($B$1,8,1), 'All Transactions'!A:A, "<"&DATE($B$1,9,1) )),0) )))} -> 0 | R4: =B4 - Q4 -> 10 | S4: {=MAP(A4:A1001, LAMBDA(cat, IF(cat="","", IFERROR(ABS(SUMIFS( 'All Transactions'!C:C, 'All Transactions'!D:D, cat, 'All Transactions'!A:A, ">="&DATE($B$1,9,1), 'All Transactions'!A:A, "<"&DATE($B$1,10,1) )),0) )))} -> 0 | T4: =B4 - S4 -> 10 | U4: {=MAP(A4:A1001, LAMBDA(cat, IF(cat="","", IFERROR(ABS(SUMIFS( 'All Transactions'!C:C, 'All Transactions'!D:D, cat, 'All Transactions'!A:A, ">="&DATE($B$1,10,1), 'All Transactions'!A:A, "<"&DATE($B$1,11,1) )),0) )))} -> 0 | V4: =B4 - U4 -> 10 | W4: {=MAP(A4:A1001, LAMBDA(cat, IF(cat="","", IFERROR(ABS(SUMIFS( 'All Transactions'!C:C, 'All Transactions'!D:D, cat, 'All Transactions'!A:A, ">="&DATE($B$1,11,1), 'All Transactions'!A:A, "<"&DATE($B$1,12,1) )),0) )))} -> 0 | X4: =B4 - W4 -> 10 | Y4: {=MAP(A4:A1001, LAMBDA(cat, IF(cat="","", IFERROR(ABS(SUMIFS( 'All Transactions'!C:C, 'All Transactions'!D:D, cat, 'All Transactions'!A:A, ">="&DATE($B$1,12,1), 'All Transactions'!A:A, "<"&DATE($B$1+1,1,1) )),0) )))} -> 0 | Z4: =B4 - Y4 -> 10
A5: =IFERROR(__xludf.DUMMYFUNCTION("""COMPUTED_VALUE"""),"Bar/ Alcohol") -> Bar/ Alcohol | B5: =IFERROR(VLOOKUP(A5,'Living Expenses'!J:K,2,FALSE),0) -> 100 | C5: 0 | D5: =B5 - C5 -> 100 | E5: 0 | F5: =B5 - E5 -> 100 | G5: 56.73 | H5: =B5 - G5 -> 43.27 | I5: 0 | J5: =B5 - I5 -> 100 | K5: 0 | L5: =B5 - K5 -> 100 | M5: 0 | N5: =B5 - M5 -> 100 | O5: 0 | P5: =B5 - O5 -> 100 | Q5: 0 | R5: =B5 - Q5 -> 100 | S5: 0 | T5: =B5 - S5 -> 100 | U5: 0 | V5: =B5 - U5 -> 100 | W5: 0 | X5: =B5 - W5 -> 100 | Y5: 0 | Z5: =B5 - Y5 -> 100
A6: =IFERROR(__xludf.DUMMYFUNCTION("""COMPUTED_VALUE"""),"Business Expenses") -> Business Expenses | B6: =IFERROR(VLOOKUP(A6,'Living Expenses'!J:K,2,FALSE),0) -> 84 | C6: 0 | D6: =B6 - C6 -> 84 | E6: 0 | F6: =B6 - E6 -> 84 | G6: 155.96 | H6: =B6 - G6 -> -71.96 | I6: 509.19 | J6: =B6 - I6 -> -425.19 | K6: 0 | L6: =B6 - K6 -> 84 | M6: 0 | N6: =B6 - M6 -> 84 | O6: 0 | P6: =B6 - O6 -> 84 | Q6: 0 | R6: =B6 - Q6 -> 84 | S6: 0 | T6: =B6 - S6 -> 84 | U6: 0 | V6: =B6 - U6 -> 84 | W6: 0 | X6: =B6 - W6 -> 84 | Y6: 0 | Z6: =B6 - Y6 -> 84
A7: =IFERROR(__xludf.DUMMYFUNCTION("""COMPUTED_VALUE"""),"Coffee") -> Coffee | B7: =IFERROR(VLOOKUP(A7,'Living Expenses'!J:K,2,FALSE),0) -> 84 | C7: 0 | D7: =B7 - C7 -> 84 | E7: 0 | F7: =B7 - E7 -> 84 | G7: 30.18 | H7: =B7 - G7 -> 53.82 | I7: 36.49 | J7: =B7 - I7 -> 47.51 | K7: 0 | L7: =B7 - K7 -> 84 | M7: 0 | N7: =B7 - M7 -> 84 | O7: 0 | P7: =B7 - O7 -> 84 | Q7: 0 | R7: =B7 - Q7 -> 84 | S7: 0 | T7: =B7 - S7 -> 84 | U7: 0 | V7: =B7 - U7 -> 84 | W7: 0 | X7: =B7 - W7 -> 84 | Y7: 0 | Z7: =B7 - Y7 -> 84
A8: =IFERROR(__xludf.DUMMYFUNCTION("""COMPUTED_VALUE"""),"Dining") -> Dining | B8: =IFERROR(VLOOKUP(A8,'Living Expenses'!J:K,2,FALSE),0) -> 320 | C8: 0 | D8: =B8 - C8 -> 320 | E8: 0 | F8: =B8 - E8 -> 320 | G8: 88.79 | H8: =B8 - G8 -> 231.21 | I8: 87.71 | J8: =B8 - I8 -> 232.29 | K8: 0 | L8: =B8 - K8 -> 320 | M8: 0 | N8: =B8 - M8 -> 320 | O8: 0 | P8: =B8 - O8 -> 320 | Q8: 0 | R8: =B8 - Q8 -> 320 | S8: 0 | T8: =B8 - S8 -> 320 | U8: 0 | V8: =B8 - U8 -> 320 | W8: 0 | X8: =B8 - W8 -> 320 | Y8: 0 | Z8: =B8 - Y8 -> 320
A9: =IFERROR(__xludf.DUMMYFUNCTION("""COMPUTED_VALUE"""),"Entertainment") -> Entertainment | B9: =IFERROR(VLOOKUP(A9,'Living Expenses'!J:K,2,FALSE),0) -> 47.5 | C9: 0 | D9: =B9 - C9 -> 47.5 | E9: 0 | F9: =B9 - E9 -> 47.5 | G9: 127.99 | H9: =B9 - G9 -> -80.49 | I9: 34.75 | J9: =B9 - I9 -> 12.75 | K9: 0 | L9: =B9 - K9 -> 47.5 | M9: 0 | N9: =B9 - M9 -> 47.5 | O9: 0 | P9: =B9 - O9 -> 47.5 | Q9: 0 | R9: =B9 - Q9 -> 47.5 | S9: 0 | T9: =B9 - S9 -> 47.5 | U9: 0 | V9: =B9 - U9 -> 47.5 | W9: 0 | X9: =B9 - W9 -> 47.5 | Y9: 0 | Z9: =B9 - Y9 -> 47.5
A10: =IFERROR(__xludf.DUMMYFUNCTION("""COMPUTED_VALUE"""),"Groceries") -> Groceries | B10: =IFERROR(VLOOKUP(A10,'Living Expenses'!J:K,2,FALSE),0) -> 500 | C10: 0 | D10: =B10 - C10 -> 500 | E10: 0 | F10: =B10 - E10 -> 500 | G10: 220.72 | H10: =B10 - G10 -> 279.28 | I10: 372.32 | J10: =B10 - I10 -> 127.68 | K10: 0 | L10: =B10 - K10 -> 500 | M10: 0 | N10: =B10 - M10 -> 500 | O10: 0 | P10: =B10 - O10 -> 500 | Q10: 0 | R10: =B10 - Q10 -> 500 | S10: 0 | T10: =B10 - S10 -> 500 | U10: 0 | V10: =B10 - U10 -> 500 | W10: 0 | X10: =B10 - W10 -> 500 | Y10: 0 | Z10: =B10 - Y10 -> 500
A11: =IFERROR(__xludf.DUMMYFUNCTION("""COMPUTED_VALUE"""),"Insurance") -> Insurance | B11: =IFERROR(VLOOKUP(A11,'Living Expenses'!J:K,2,FALSE),0) -> 23 | C11: 0 | D11: =B11 - C11 -> 23 | E11: 0 | F11: =B11 - E11 -> 23 | G11: 366 | H11: =B11 - G11 -> -343 | I11: 0 | J11: =B11 - I11 -> 23 | K11: 0 | L11: =B11 - K11 -> 23 | M11: 0 | N11: =B11 - M11 -> 23 | O11: 0 | P11: =B11 - O11 -> 23 | Q11: 0 | R11: =B11 - Q11 -> 23 | S11: 0 | T11: =B11 - S11 -> 23 | U11: 0 | V11: =B11 - U11 -> 23 | W11: 0 | X11: =B11 - W11 -> 23 | Y11: 0 | Z11: =B11 - Y11 -> 23
A12: =IFERROR(__xludf.DUMMYFUNCTION("""COMPUTED_VALUE"""),"Misc") -> Misc | B12: =IFERROR(VLOOKUP(A12,'Living Expenses'!J:K,2,FALSE),0) -> 30 | C12: 0 | D12: =B12 - C12 -> 30 | E12: 0 | F12: =B12 - E12 -> 30 | G12: 34.51 | H12: =B12 - G12 -> -4.51 | I12: 0 | J12: =B12 - I12 -> 30 | K12: 0 | L12: =B12 - K12 -> 30 | M12: 0 | N12: =B12 - M12 -> 30 | O12: 0 | P12: =B12 - O12 -> 30 | Q12: 0 | R12: =B12 - Q12 -> 30 | S12: 0 | T12: =B12 - S12 -> 30 | U12: 0 | V12: =B12 - U12 -> 30 | W12: 0 | X12: =B12 - W12 -> 30 | Y12: 0 | Z12: =B12 - Y12 -> 30
A13: =IFERROR(__xludf.DUMMYFUNCTION("""COMPUTED_VALUE"""),"Other Services") -> Other Services | B13: =IFERROR(VLOOKUP(A13,'Living Expenses'!J:K,2,FALSE),0) -> 18 | C13: 0 | D13: =B13 - C13 -> 18 | E13: 0 | F13: =B13 - E13 -> 18 | G13: 1.25 | H13: =B13 - G13 -> 16.75 | I13: 6.37 | J13: =B13 - I13 -> 11.63 | K13: 0 | L13: =B13 - K13 -> 18 | M13: 0 | N13: =B13 - M13 -> 18 | O13: 0 | P13: =B13 - O13 -> 18 | Q13: 0 | R13: =B13 - Q13 -> 18 | S13: 0 | T13: =B13 - S13 -> 18 | U13: 0 | V13: =B13 - U13 -> 18 | W13: 0 | X13: =B13 - W13 -> 18 | Y13: 0 | Z13: =B13 - Y13 -> 18
A14: =IFERROR(__xludf.DUMMYFUNCTION("""COMPUTED_VALUE"""),"Rent") -> Rent | B14: =IFERROR(VLOOKUP(A14,'Living Expenses'!J:K,2,FALSE),0) -> 1327 | C14: 0 | D14: =B14 - C14 -> 1327 | E14: 0 | F14: =B14 - E14 -> 1327 | G14: 1327 | H14: =B14 - G14 -> 0 | I14: 1327 | J14: =B14 - I14 -> 0 | K14: 0 | L14: =B14 - K14 -> 1327 | M14: 0 | N14: =B14 - M14 -> 1327 | O14: 0 | P14: =B14 - O14 -> 1327 | Q14: 0 | R14: =B14 - Q14 -> 1327 | S14: 0 | T14: =B14 - S14 -> 1327 | U14: 0 | V14: =B14 - U14 -> 1327 | W14: 0 | X14: =B14 - W14 -> 1327 | Y14: 0 | Z14: =B14 - Y14 -> 1327
A15: =IFERROR(__xludf.DUMMYFUNCTION("""COMPUTED_VALUE"""),"Shopping") -> Shopping | B15: =IFERROR(VLOOKUP(A15,'Living Expenses'!J:K,2,FALSE),0) -> 97 | C15: 0 | D15: =B15 - C15 -> 97 | E15: 0 | F15: =B15 - E15 -> 97 | G15: 439.26 | H15: =B15 - G15 -> -342.26 | I15: 333.56 | J15: =B15 - I15 -> -236.56 | K15: 0 | L15: =B15 - K15 -> 97 | M15: 0 | N15: =B15 - M15 -> 97 | O15: 0 | P15: =B15 - O15 -> 97 | Q15: 0 | R15: =B15 - Q15 -> 97 | S15: 0 | T15: =B15 - S15 -> 97 | U15: 0 | V15: =B15 - U15 -> 97 | W15: 0 | X15: =B15 - W15 -> 97 | Y15: 0 | Z15: =B15 - Y15 -> 97
A16: =IFERROR(__xludf.DUMMYFUNCTION("""COMPUTED_VALUE"""),"Subscriptions") -> Subscriptions | B16: =IFERROR(VLOOKUP(A16,'Living Expenses'!J:K,2,FALSE),0) -> 132 | C16: 0 | D16: =B16 - C16 -> 132 | E16: 0 | F16: =B16 - E16 -> 132 | G16: 39.99 | H16: =B16 - G16 -> 92.01 | I16: 81.84 | J16: =B16 - I16 -> 50.16 | K16: 0 | L16: =B16 - K16 -> 132 | M16: 0 | N16: =B16 - M16 -> 132 | O16: 0 | P16: =B16 - O16 -> 132 | Q16: 0 | R16: =B16 - Q16 -> 132 | S16: 0 | T16: =B16 - S16 -> 132 | U16: 0 | V16: =B16 - U16 -> 132 | W16: 0 | X16: =B16 - W16 -> 132 | Y16: 0 | Z16: =B16 - Y16 -> 132
A17: =IFERROR(__xludf.DUMMYFUNCTION("""COMPUTED_VALUE"""),"Transportation") -> Transportation | B17: =IFERROR(VLOOKUP(A17,'Living Expenses'!J:K,2,FALSE),0) -> 25 | C17: 0 | D17: =B17 - C17 -> 25 | E17: 0 | F17: =B17 - E17 -> 25 | G17: 214.42 | H17: =B17 - G17 -> -189.42 | I17: 93.23 | J17: =B17 - I17 -> -68.23 | K17: 0 | L17: =B17 - K17 -> 25 | M17: 0 | N17: =B17 - M17 -> 25 | O17: 0 | P17: =B17 - O17 -> 25 | Q17: 0 | R17: =B17 - Q17 -> 25 | S17: 0 | T17: =B17 - S17 -> 25 | U17: 0 | V17: =B17 - U17 -> 25 | W17: 0 | X17: =B17 - W17 -> 25 | Y17: 0 | Z17: =B17 - Y17 -> 25
A18: =IFERROR(__xludf.DUMMYFUNCTION("""COMPUTED_VALUE"""),"Travel") -> Travel | B18: =IFERROR(VLOOKUP(A18,'Living Expenses'!J:K,2,FALSE),0) -> 142 | C18: 0 | D18: =B18 - C18 -> 142 | E18: 0 | F18: =B18 - E18 -> 142 | G18: 0 | H18: =B18 - G18 -> 142 | I18: 0 | J18: =B18 - I18 -> 142 | K18: 0 | L18: =B18 - K18 -> 142 | M18: 0 | N18: =B18 - M18 -> 142 | O18: 0 | P18: =B18 - O18 -> 142 | Q18: 0 | R18: =B18 - Q18 -> 142 | S18: 0 | T18: =B18 - S18 -> 142 | U18: 0 | V18: =B18 - U18 -> 142 | W18: 0 | X18: =B18 - W18 -> 142 | Y18: 0 | Z18: =B18 - Y18 -> 142
A19: =IFERROR(__xludf.DUMMYFUNCTION("""COMPUTED_VALUE"""),"Utilities") -> Utilities | B19: =IFERROR(VLOOKUP(A19,'Living Expenses'!J:K,2,FALSE),0) -> 135 | C19: 0 | D19: =B19 - C19 -> 135 | E19: 0 | F19: =B19 - E19 -> 135 | G19: 0 | H19: =B19 - G19 -> 135 | I19: 0 | J19: =B19 - I19 -> 135 | K19: 0 | L19: =B19 - K19 -> 135 | M19: 0 | N19: =B19 - M19 -> 135 | O19: 0 | P19: =B19 - O19 -> 135 | Q19: 0 | R19: =B19 - Q19 -> 135 | S19: 0 | T19: =B19 - S19 -> 135 | U19: 0 | V19: =B19 - U19 -> 135 | W19: 0 | X19: =B19 - W19 -> 135 | Y19: 0 | Z19: =B19 - Y19 -> 135
B20: =IFERROR(VLOOKUP(A20,'Living Expenses'!J:K,2,FALSE),0) -> 0 | D20: =B20 - C20 -> 0 | F20: =B20 - E20 -> 0 | H20: =B20 - G20 -> 0 | J20: =B20 - I20 -> 0 | L20: =B20 - K20 -> 0 | N20: =B20 - M20 -> 0 | P20: =B20 - O20 -> 0 | R20: =B20 - Q20 -> 0 | T20: =B20 - S20 -> 0 | V20: =B20 - U20 -> 0 | X20: =B20 - W20 -> 0 | Z20: =B20 - Y20 -> 0
B21: =IFERROR(VLOOKUP(A21,'Living Expenses'!J:K,2,FALSE),0) -> 0 | D21: =B21 - C21 -> 0 | F21: =B21 - E21 -> 0 | H21: =B21 - G21 -> 0 | J21: =B21 - I21 -> 0 | L21: =B21 - K21 -> 0 | N21: =B21 - M21 -> 0 | P21: =B21 - O21 -> 0 | R21: =B21 - Q21 -> 0 | T21: =B21 - S21 -> 0 | V21: =B21 - U21 -> 0 | X21: =B21 - W21 -> 0 | Z21: =B21 - Y21 -> 0
B22: =IFERROR(VLOOKUP(A22,'Living Expenses'!J:K,2,FALSE),0) -> 0 | D22: =B22 - C22 -> 0 | F22: =B22 - E22 -> 0 | H22: =B22 - G22 -> 0 | J22: =B22 - I22 -> 0 | L22: =B22 - K22 -> 0 | N22: =B22 - M22 -> 0 | P22: =B22 - O22 -> 0 | R22: =B22 - Q22 -> 0 | T22: =B22 - S22 -> 0 | V22: =B22 - U22 -> 0 | X22: =B22 - W22 -> 0 | Z22: =B22 - Y22 -> 0

Sheet Capitol One Transactions
A1: Transaction Date | B1: Posted Date | C1: Card No. | D1: Description | E1: Category | F1: Debit | G1: Budgeting Category | I1: Instructions: Statements & Documents -> Download Transactions -> CSV -> Open in Numbers & Copy -> Delete 'payments' rows -> drag down 'Budgeting Category' column
A2: 46111 | B2: 46112 | C2: 9518 | D2: TST*SIGHTGLASS COFFEE - | E2: Coffee | F2: 5.83 | G2: =IFERROR(VLOOKUP(TRIM(E2), 'Expense Category Mapping'!A:B, 2, FALSE), "Misc") -> Coffee
A3: 46111 | B3: 46112 | C3: 9518 | D3: IKEA SAN FRAN | E3: Merchandise | F3: 21.67 | G3: =IFERROR(VLOOKUP(TRIM(E3), 'Expense Category Mapping'!A:B, 2, FALSE), "Misc") -> Shopping
A4: 46110 | B4: 46112 | C4: 9518 | D4: CLIPPER TRANSIT FARE | E4: Other Travel | F4: 2.85 | G4: =IFERROR(VLOOKUP(TRIM(E4), 'Expense Category Mapping'!A:B, 2, FALSE), "Misc") -> Transportation | I4: Capitol One Categories to map/ change
A5: 46111 | B5: 46112 | C5: 9518 | D5: SPIN* PENDING.BIRD.CO | E5: Other Travel | F5: 5.22 | G5: =IFERROR(VLOOKUP(TRIM(E5), 'Expense Category Mapping'!A:B, 2, FALSE), "Misc") -> Transportation | I5: Google One | J5: Entertainment | K5: Change to 'Subscriptions'
A6: 46111 | B6: 46111 | C6: 9518 | D6: THUMBTACK 9443567618 | E6: Professional Services | F6: 24.46 | G6: =IFERROR(VLOOKUP(TRIM(E6), 'Expense Category Mapping'!A:B, 2, FALSE), "Misc") -> Business Expenses | I6: Payment/Credit | J6: Delete Row
A7: 46109 | B7: 46111 | C7: 9518 | D7: CAMPUS | E7: Bar/ Alcohol | F7: 33.79 | G7: =IFERROR(VLOOKUP(TRIM(E7), 'Expense Category Mapping'!A:B, 2, FALSE), "Misc") -> Bar/ Alcohol | I7: FANDANGO | J7: Subscriptions | K7: Change to 'Entertainment'
A8: 46110 | B8: 46111 | C8: 9518 | D8: TRUST THE UNIVERSE | E8: Entertainment | F8: 68 | G8: =IFERROR(VLOOKUP(TRIM(E8), 'Expense Category Mapping'!A:B, 2, FALSE), "Misc") -> Entertainment | I8: TRADER JOES | J8: Merchandise | K8: Change to 'Grocery'
A9: 46109 | B9: 46111 | C9: 9518 | D9: PAYPAL *UBER | E9: Other Travel | F9: 10.91 | G9: =IFERROR(VLOOKUP(TRIM(E9), 'Expense Category Mapping'!A:B, 2, FALSE), "Misc") -> Transportation | I9: POLK STREET MARKET | J9: Merchandise | K9: Change to 'Dining'
A10: 46108 | B10: 46111 | C10: 9518 | D10: CLIPPER TRANSIT FARE | E10: Other Travel | F10: 2.85 | G10: =IFERROR(VLOOKUP(TRIM(E10), 'Expense Category Mapping'!A:B, 2, FALSE), "Misc") -> Transportation
A11: 46108 | B11: 46109 | C11: 9518 | D11: MR LIQUOR NORTH POINT | E11: Bar/ Alcohol | F11: 11.94 | G11: =IFERROR(VLOOKUP(TRIM(E11), 'Expense Category Mapping'!A:B, 2, FALSE), "Misc") -> Bar/ Alcohol
A12: 46108 | B12: 46109 | C12: 9518 | D12: Adobe Inc | E12: Subscriptions | F12: 39.99 | G12: =IFERROR(VLOOKUP(TRIM(E12), 'Expense Category Mapping'!A:B, 2, FALSE), "Misc") -> Subscriptions
A13: 46108 | B13: 46109 | C13: 9518 | D13: TESLA, INC. | E13: Other Travel | F13: 7.95 | G13: =IFERROR(VLOOKUP(TRIM(E13), 'Expense Category Mapping'!A:B, 2, FALSE), "Misc") -> Transportation
A14: 46107 | B14: 46108 | C14: 9518 | D14: WALGREENS #5599 | E14: Health Care | F14: 26.51 | G14: =IFERROR(VLOOKUP(TRIM(E14), 'Expense Category Mapping'!A:B, 2, FALSE), "Misc") -> Misc
A15: 46105 | B15: 46106 | C15: 9518 | D15: SQ *CAFE #27255 UNION SQU | E15: Dining | F15: 6.75 | G15: =IFERROR(VLOOKUP(TRIM(E15), 'Expense Category Mapping'!A:B, 2, FALSE), "Misc") -> Dining
A16: 46104 | B16: 46105 | C16: 9518 | D16: THUMBTACK 9443567618 | E16: Professional Services | F16: 32.34 | G16: =IFERROR(VLOOKUP(TRIM(E16), 'Expense Category Mapping'!A:B, 2, FALSE), "Misc") -> Business Expenses
A17: 46104 | B17: 46105 | C17: 9518 | D17: BI-RITE MARKET | E17: Merchandise | F17: 11.96 | G17: =IFERROR(VLOOKUP(TRIM(E17), 'Expense Category Mapping'!A:B, 2, FALSE), "Misc") -> Shopping
A18: 46105 | B18: 46105 | C18: 9518 | D18: Google One | E18: Entertainment | F18: 9.99 | G18: =IFERROR(VLOOKUP(TRIM(E18), 'Expense Category Mapping'!A:B, 2, FALSE), "Misc") -> Entertainment
A19: 46103 | B19: 46105 | C19: 9518 | D19: POLK STREET MARKET | E19: Merchandise | F19: 19.16 | G19: =IFERROR(VLOOKUP(TRIM(E19), 'Expense Category Mapping'!A:B, 2, FALSE), "Misc") -> Shopping
A20: 46103 | B20: 46104 | C20: 9518 | D20: THUMBTACK 9443567618 | E20: Professional Services | F20: 17.66 | G20: =IFERROR(VLOOKUP(TRIM(E20), 'Expense Category Mapping'!A:B, 2, FALSE), "Misc") -> Business Expenses
A21: 46103 | B21: 46104 | C21: 9518 | D21: COLE HARDWARE | E21: Merchandise | F21: 17.77 | G21: =IFERROR(VLOOKUP(TRIM(E21), 'Expense Category Mapping'!A:B, 2, FALSE), "Misc") -> Shopping
... A56: 46083 | B56: 46084 | C56: 9518 | D56: COSTCO WHSE #0474 | E56: Grocery | F56: 3.26 | G56: =IFERROR(VLOOKUP(TRIM(E56), 'Expense Category Mapping'!A:B, 2, FALSE), "Misc") -> Groceries
G57: =IFERROR(VLOOKUP(TRIM(E57), 'Expense Category Mapping'!A:B, 2, FALSE), "Misc") -> Misc
G58: =IFERROR(VLOOKUP(TRIM(E58), 'Expense Category Mapping'!A:B, 2, FALSE), "Misc") -> Misc
G59: =IFERROR(VLOOKUP(TRIM(E59), 'Expense Category Mapping'!A:B, 2, FALSE), "Misc") -> Misc
A60: 46141 | B60: 46142 | C60: 9518 | D60: SQ *ANOTHER CAFE | E60: Coffee | F60: 1.5 | G60: =IFERROR(VLOOKUP(TRIM(E60), 'Expense Category Mapping'!A:B, 2, FALSE), "Misc") -> Coffee
A61: 46141 | B61: 46142 | C61: 9518 | D61: SQ *ANOTHER CAFE | E61: Coffee | F61: 6.75 | G61: =IFERROR(VLOOKUP(TRIM(E61), 'Expense Category Mapping'!A:B, 2, FALSE), "Misc") -> Coffee
A62: 46141 | B62: 46141 | C62: 9518 | D62: APPLE.COM/BILL | E62: Internet | F62: 4.99 | G62: =IFERROR(VLOOKUP(TRIM(E62), 'Expense Category Mapping'!A:B, 2, FALSE), "Misc") -> Internet
A63: 46139 | B63: 46140 | C63: 9518 | D63: PAYPAL *UBER | E63: Other Travel | F63: 10.77 | G63: =IFERROR(VLOOKUP(TRIM(E63), 'Expense Category Mapping'!A:B, 2, FALSE), "Misc") -> Transportation
A64: 46139 | B64: 46140 | C64: 9518 | D64: Adobe Inc | E64: Subscriptions | F64: 39.99 | G64: =IFERROR(VLOOKUP(TRIM(E64), 'Expense Category Mapping'!A:B, 2, FALSE), "Misc") -> Subscriptions
A65: 46137 | B65: 46139 | C65: 9518 | D65: CLIPPER MOBILE | E65: Other Travel | F65: 20 | G65: =IFERROR(VLOOKUP(TRIM(E65), 'Expense Category Mapping'!A:B, 2, FALSE), "Misc") -> Transportation
A66: 46136 | B66: 46136 | C66: 9518 | D66: Google One | E66: Subscriptions | F66: 9.99 | G66: =IFERROR(VLOOKUP(TRIM(E66), 'Expense Category Mapping'!A:B, 2, FALSE), "Misc") -> Subscriptions
A67: 46134 | B67: 46136 | C67: 9518 | D67: TST*HARAZ COFFEE- FRANKL | E67: Coffee | F67: 3.81 | G67: =IFERROR(VLOOKUP(TRIM(E67), 'Expense Category Mapping'!A:B, 2, FALSE), "Misc") -> Coffee
A68: 46135 | B68: 46135 | C68: 9518 | D68: NOVA PRO | E68: Subscriptions | F68: 12.99 | G68: =IFERROR(VLOOKUP(TRIM(E68), 'Expense Category Mapping'!A:B, 2, FALSE), "Misc") -> Subscriptions
A69: 46134 | B69: 46134 | C69: 9518 | D69: FANDANGO * | E69: Subscriptions | F69: 15.88 | G69: =IFERROR(VLOOKUP(TRIM(E69), 'Expense Category Mapping'!A:B, 2, FALSE), "Misc") -> Subscriptions
A70: 46132 | B70: 46132 | C70: 9518 | D70: HOSTINGER* HOSTINGER.C | E70: Internet | F70: 17.99 | G70: =IFERROR(VLOOKUP(TRIM(E70), 'Expense Category Mapping'!A:B, 2, FALSE), "Misc") -> Internet
A71: 46131 | B71: 46132 | C71: 9518 | D71: PAYPAL *UBER | E71: Other Travel | F71: 14.43 | G71: =IFERROR(VLOOKUP(TRIM(E71), 'Expense Category Mapping'!A:B, 2, FALSE), "Misc") -> Transportation
... A108: 46114 | B108: 46116 | C108: 9518 | D108: CLIPPER TRANSIT FARE | E108: Other Travel | F108: 4.6 | G108: =IFERROR(VLOOKUP(TRIM(E108), 'Expense Category Mapping'!A:B, 2, FALSE), "Misc") -> Transportation
G109: =IFERROR(VLOOKUP(TRIM(E109), 'Expense Category Mapping'!A:B, 2, FALSE), "Misc") -> Misc
G110: =IFERROR(VLOOKUP(TRIM(E110), 'Expense Category Mapping'!A:B, 2, FALSE), "Misc") -> Misc
...

Sheet Venmo Transactions
A1: Datetime | B1: Type | C1: Status | D1: Note | E1: From | F1: To | G1: Amount (total) | H1: Budget Category | J1: Instructions: Statements -> Month -> CSV-> Open in Numbers & Copy -> Manually add budget category -> Delete sold items
A2: 46082 | D2: Null | G2: 0 | H2: Coffee
A3: 46082 | D3: Null | G3: 0 | H3: Dining
A4: 46082 | D4: Null | G4: 0 | H4: Shopping
A5: 46082 | D5: Null | G5: 0 | H5: Transportation
A6: 46082 | D6: Null | G6: 0 | H6: Business Expenses
A7: 46082 | D7: Null | G7: 0 | H7: Entertainment
A8: 46082 | D8: Null | G8: 0 | H8: Groceries
A9: 46082 | D9: Null | G9: 0 | H9: Subscriptions
A10: 46082 | D10: Null | G10: 0 | H10: Bar/ Alcohol
A11: 46082 | D11: Null | G11: 0 | H11: AI Fees
A12: 46082 | D12: Null | G12: 0 | H12: Internet
A13: 46082 | D13: Null | G13: 0 | H13: Car Rental
... A19: 46082 | D19: Null | G19: 0 | H19: Travel
A20: 46084.797 | B20: Payment | C20: Complete | D20: Painting! | E20: Luke Stimson | F20: georgia bracchi | G20: -20 | H20: Shopping
A21: 46090.711 | B21: Payment | C21: Complete | D21: Shelves | E21: Luke Stimson | F21: Victoria Delgado | G21: -25 | H21: Shopping
A22: 46096.93 | B22: Payment | C22: Complete | D22: Chairs | E22: Will Boudreau | F22: Luke Stimson | G22: 25 | H22: Shopping
A23: 46096.936 | B23: Charge | C23: Complete | D23: 🪩 | E23: Luke Stimson | F23: Kylan O'Connor | G23: 37 | H23: Entertainment
A24: 46097.045 | B24: Payment | C24: Complete | D24: Notebook + candle + pyrex | E24: Will Boudreau | F24: Luke Stimson | G24: 55 | H24: Shopping
A25: 46100.71 | B25: Payment | C25: Complete | D25: Target Haul | E25: Eric Manzo | F25: Luke Stimson | G25: 20 | H25: Shopping
A26: 46100.714 | B26: Payment | C26: Complete | D26: Toallas de papel | E26: Luke Stimson | F26: Eric Manzo | G26: -5 | H26: Shopping
A27: 46100.769 | B27: Payment | C27: Complete | D27: Target | E27: Will Boudreau | F27: Luke Stimson | G27: 20 | H27: Shopping
A28: 46101.154 | B28: Payment | C28: Complete | D28: Rack | E28: Luke Stimson | F28: Megan Guldan | G28: -5 | H28: Shopping
A29: 46102.903 | B29: Payment | C29: Complete | D29: Bier | E29: Luke Stimson | F29: Christopher Civilikas | G29: -11 | H29: Bar/ Alcohol
A30: 46111.911 | B30: Payment | C30: Complete | D30: Grubby chicken | E30: Luke Stimson | F30: Kylan O'Connor | G30: -18.5 | H30: Dining
A34: 46113.167 | B34: Payment | C34: Complete | D34: April 🏠 | E34: Luke Stimson | F34: Eric Manzo | G34: -1327 | H34: Rent
... A51: 46142.638 | B51: Payment | C51: Complete | D51: MJ Movie! | E51: Luke Stimson | F51: Eric Manzo | G51: -8 | H51: Entertainment

Sheet Other Transactions
A1: Transaction Date | B1: Description | C1: Amount | D1: Budget Category | E1: Source
A2: 46082 | B2: Rent | C2: 1327 | D2: Rent | E2: Venmo
A3: 46093 | B3: Groceries | C3: -64.84 | D3: Groceries | E3: EBT
A4: 46094 | B4: Groceries | C4: -4.74 | D4: Groceries | E4: EBT
A5: 46099 | B5: Groceries | C5: -46.05 | D5: Groceries | E5: EBT
A6: 46104 | B6: Groceries | C6: -44.81 | D6: Groceries | E6: EBT
A7: 46108 | B7: Groceries | C7: -6.99 | D7: Groceries | E7: EBT
A8: 46113 | B8: Groceries | C8: -94.73 | D8: Groceries | E8: EBT
A9: 46121 | B9: Groceries | C9: -64.19 | D9: Groceries | E9: EBT
A10: 46134 | B10: Groceries | C10: -68.23 | D10: Groceries | E10: EBT
A11: 46141 | B11: Groceries | C11: -18 | D11: Groceries | E11: EBT

Sheet Expense Category Mapping
A1: Capitol One Category | B1: Budget Category
A2: Coffee | B2: Coffee
A3: Dining | B3: Dining
A4: Merchandise | B4: Shopping
A5: Other Travel | B5: Transportation
A6: Professional Services | B6: Business Expenses
A7: Entertainment | B7: Entertainment
A8: Grocery | B8: Groceries
A9: Subscriptions | B9: Subscriptions
A10: Bar/ Alcohol | B10: Bar/ Alcohol
A11: AI Fees | B11: AI Fees
A12: Internet | B12: Internet
... A19: Travel | B19: Travel

Sheet CA v FEDERAL Taxable Income
A1: CS vs Federal Taxable Income
A2: Step | B2: Description | C2: Key Value | D2: How It's Used | F2: NEED TO ADD TO TAXES
A3: 1 | B3: Total Gross Income | C3: W-2 wages + Net freelance profit (Schedule C) + other income | D3: Starting point for both returns | F3: * Self-Employment Tax Note: Freelance income incurs self-employment tax (~15.3% on net profit). You get a deduction for half of this tax on your federal return only, which lowers your federal AGI.
A4: 2 | B4: Federal Above-the-Line Adjustments | C4: Half self-employment tax, self-employed health insurance, etc. | D4: Subtract from gross income | F4: Add to Sheets: New row "Half SE Tax Deduction (Federal only)" under "Freelance 'Above-the-line' Deductions". Subtract it for Federal AGI only — do not subtract for California Taxable Income. (With your small freelance earnings, this will be minor, likely <$200.)
A5: 3 | B5: Federal Adjusted Gross Income (AGI) | C5: Line 11b on federal Form 1040 | D5: Base for federal taxable income; also starting point for California
A6: 4 | B6: Federal Standard Deduction (or Itemized) | C6: $15,750 (single, 2025) | D6: Subtract from Federal AGI → Federal Taxable Income
A7: 5 | B7: California Adjustments (Schedule CA Part I) | C7: Additions or subtractions for items where CA differs from federal (e.g., certain income exclusions, deductions not allowed in CA) | D7: Applied to Federal AGI
A8: 6 | B8: California AGI | C8: Federal AGI + CA additions – CA subtractions (from Schedule CA) | D8: Base for California return (entered on Form 540 line 13, then adjusted)
A9: 7 | B9: California Standard Deduction (or Itemized) | C9: $5,706 (single, 2025) | D9: Subtract from California AGI → California Taxable Income
A10: 8 | B10: Final Tax Calculation | C10: - | D10: Federal tax on Federal Taxable Income California tax on California Taxable Income

Sheet old - Summary
A1: Category | B1: Budget | C1: Mar Spent | D1: Mar Diff | E1: Apr Spent | F1: April Diff | G1: May Spent | H1: May Diff | I1: June Spent | J1: June Diff
A2: =IFERROR(__xludf.DUMMYFUNCTION("SORT(UNIQUE(FILTER('Living Expenses'!J2:J1000,'Living Expenses'!J2:J1000<>"""")))"),"AI Fees") -> AI Fees | B2: =IFERROR(VLOOKUP(A2,'Living Expenses'!J:K,2,FALSE),0) -> 10 | C2: =ABS(SUMIFS( 'All Transactions'!C:C, 'All Transactions'!D:D, $A2, 'All Transactions'!A:A, ">="&DATE(2026,3,1), 'All Transactions'!A:A, "<="&EOMONTH(DATE(2026,3,1),0) )) -> 2.03 | D2: =B2-$C2 -> 7.97 | E2: =ABS(SUMIFS( 'All Transactions'!C:C, 'All Transactions'!D:D, $A2, 'All Transactions'!A:A, ">="&DATE(2026,4,1), 'All Transactions'!A:A, "<="&EOMONTH(DATE(2026,4,1),0) )) -> 0 | F2: =B2-$E2 -> 10 | G2: =ABS(SUMIFS( 'All Transactions'!G:G, 'All Transactions'!H:H, $A2, 'All Transactions'!E:E, ">="&DATE(2026,5,1), 'All Transactions'!E:E, "<="&EOMONTH(DATE(2026,5,1),0) )) -> 0 | H2: =F2-$C2 -> 7.97 | I2: =ABS(SUMIFS( 'All Transactions'!G:G, 'All Transactions'!H:H, $A2, 'All Transactions'!E:E, ">="&DATE(2026,4,1), 'All Transactions'!E:E, "<="&EOMONTH(DATE(2026,4,1),0) )) -> 0 | J2: =F2-$E2 -> 10
A3: =IFERROR(__xludf.DUMMYFUNCTION("""COMPUTED_VALUE"""),"Bar/ Alcohol") -> Bar/ Alcohol | B3: =IFERROR(VLOOKUP(A3,'Living Expenses'!J:K,2,FALSE),0) -> 100 | C3: =ABS(SUMIFS( 'All Transactions'!C:C, 'All Transactions'!D:D, $A3, 'All Transactions'!A:A, ">="&DATE(2026,3,1), 'All Transactions'!A:A, "<="&EOMONTH(DATE(2026,3,1),0) )) -> 56.73 | D3: =B3-$C3 -> 43.27 | E3: =ABS(SUMIFS( 'All Transactions'!C:C, 'All Transactions'!D:D, $A3, 'All Transactions'!A:A, ">="&DATE(2026,4,1), 'All Transactions'!A:A, "<="&EOMONTH(DATE(2026,4,1),0) )) -> 0 | F3: =B3-$E3 -> 100 | G3: =ABS(SUMIFS( 'All Transactions'!G:G, 'All Transactions'!H:H, $A3, 'All Transactions'!E:E, ">="&DATE(2026,3,1), 'All Transactions'!E:E, "<="&EOMONTH(DATE(2026,3,1),0) )) -> 0 | H3: =F3-$C3 -> 43.27 | I3: =ABS(SUMIFS( 'All Transactions'!G:G, 'All Transactions'!H:H, $A3, 'All Transactions'!E:E, ">="&DATE(2026,4,1), 'All Transactions'!E:E, "<="&EOMONTH(DATE(2026,4,1),0) )) -> 0 | J3: =F3-$E3 -> 100
A4: =IFERROR(__xludf.DUMMYFUNCTION("""COMPUTED_VALUE"""),"Business Expenses") -> Business Expenses | B4: =IFERROR(VLOOKUP(A4,'Living Expenses'!J:K,2,FALSE),0) -> 84 | C4: =ABS(SUMIFS( 'All Transactions'!C:C, 'All Transactions'!D:D, $A4, 'All Transactions'!A:A, ">="&DATE(2026,3,1), 'All Transactions'!A:A, "<="&EOMONTH(DATE(2026,3,1),0) )) -> 155.96 | D4: =B4-$C4 -> -71.96 | E4: =ABS(SUMIFS( 'All Transactions'!C:C, 'All Transactions'!D:D, $A4, 'All Transactions'!A:A, ">="&DATE(2026,4,1), 'All Transactions'!A:A, "<="&EOMONTH(DATE(2026,4,1),0) )) -> 509.19 | F4: =B4-$E4 -> -425.19 | G4: =ABS(SUMIFS( 'All Transactions'!G:G, 'All Transactions'!H:H, $A4, 'All Transactions'!E:E, ">="&DATE(2026,3,1), 'All Transactions'!E:E, "<="&EOMONTH(DATE(2026,3,1),0) )) -> 0 | H4: =F4-$C4 -> -581.15 | I4: =ABS(SUMIFS( 'All Transactions'!G:G, 'All Transactions'!H:H, $A4, 'All Transactions'!E:E, ">="&DATE(2026,4,1), 'All Transactions'!E:E, "<="&EOMONTH(DATE(2026,4,1),0) )) -> 0 | J4: =F4-$E4 -> -934.38
A5: =IFERROR(__xludf.DUMMYFUNCTION("""COMPUTED_VALUE"""),"Coffee") -> Coffee | B5: =IFERROR(VLOOKUP(A5,'Living Expenses'!J:K,2,FALSE),0) -> 84 | C5: =ABS(SUMIFS( 'All Transactions'!C:C, 'All Transactions'!D:D, $A5, 'All Transactions'!A:A, ">="&DATE(2026,3,1), 'All Transactions'!A:A, "<="&EOMONTH(DATE(2026,3,1),0) )) -> 30.18 | D5: =B5-$C5 -> 53.82 | E5: =ABS(SUMIFS( 'All Transactions'!C:C, 'All Transactions'!D:D, $A5, 'All Transactions'!A:A, ">="&DATE(2026,4,1), 'All Transactions'!A:A, "<="&EOMONTH(DATE(2026,4,1),0) )) -> 36.49 | F5: =B5-$E5 -> 47.51 | G5: =ABS(SUMIFS( 'All Transactions'!G:G, 'All Transactions'!H:H, $A5, 'All Transactions'!E:E, ">="&DATE(2026,3,1), 'All Transactions'!E:E, "<="&EOMONTH(DATE(2026,3,1),0) )) -> 0 | H5: =F5-$C5 -> 17.33 | I5: =ABS(SUMIFS( 'All Transactions'!G:G, 'All Transactions'!H:H, $A5, 'All Transactions'!E:E, ">="&DATE(2026,4,1), 'All Transactions'!E:E, "<="&EOMONTH(DATE(2026,4,1),0) )) -> 0 | J5: =F5-$E5 -> 11.02
A6: =IFERROR(__xludf.DUMMYFUNCTION("""COMPUTED_VALUE"""),"Dining") -> Dining | B6: =IFERROR(VLOOKUP(A6,'Living Expenses'!J:K,2,FALSE),0) -> 320 | C6: =ABS(SUMIFS( 'All Transactions'!C:C, 'All Transactions'!D:D, $A6, 'All Transactions'!A:A, ">="&DATE(2026,3,1), 'All Transactions'!A:A, "<="&EOMONTH(DATE(2026,3,1),0) )) -> 88.79 | D6: =B6-$C6 -> 231.21 | E6: =ABS(SUMIFS( 'All Transactions'!C:C, 'All Transactions'!D:D, $A6, 'All Transactions'!A:A, ">="&DATE(2026,4,1), 'All Transactions'!A:A, "<="&EOMONTH(DATE(2026,4,1),0) )) -> 87.71 | F6: =B6-$E6 -> 232.29 | G6: =ABS(SUMIFS( 'All Transactions'!G:G, 'All Transactions'!H:H, $A6, 'All Transactions'!E:E, ">="&DATE(2026,3,1), 'All Transactions'!E:E, "<="&EOMONTH(DATE(2026,3,1),0) )) -> 0 | H6: =F6-$C6 -> 143.5 | I6: =ABS(SUMIFS( 'All Transactions'!G:G, 'All Transactions'!H:H, $A6, 'All Transactions'!E:E, ">="&DATE(2026,4,1), 'All Transactions'!E:E, "<="&EOMONTH(DATE(2026,4,1),0) )) -> 0 | J6: =F6-$E6 -> 144.58
